Workbook

Sheet Table4_Cost_Benefit_Analysis
A1: Panel A. Program Costs per Participant, 2014 USD PPP | B1: Ethiopia | C1: Ghana | D1: Honduras | E1: India | F1: Pakistan | G1: Peru
A2: Notes: 2014 USD PPP costs = Nominal costs in baseline year * (US 2014 CPI/US CPI in baseline year)
A3: Total Direct Costs | B3: =Nominal_cost_bsl_year!B3*(Nominal_cost_bsl_year!B$20/Nominal_cost_bsl_year!B$19)*B$19 -> 3127.4084 | C3: =Nominal_cost_bsl_year!C3*(Nominal_cost_bsl_year!C$20/Nominal_cost_bsl_year!C$19)*C$19 -> 3512.6234 | D3: =Nominal_cost_bsl_year!D3*(Nominal_cost_bsl_year!D$20/Nominal_cost_bsl_year!D$19)*D$19 -> 2356.3169 | E3: =Nominal_cost_bsl_year!E3*(Nominal_cost_bsl_year!E$20/Nominal_cost_bsl_year!E$19)*E$19 -> 1106.6599 | F3: =Nominal_cost_bsl_year!F3*(Nominal_cost_bsl_year!F$20/Nominal_cost_bsl_year!F$19)*F$19 -> 4679.777 | G3: =Nominal_cost_bsl_year!G3*(Nominal_cost_bsl_year!G$20/Nominal_cost_bsl_year!G$19)*G$19 -> 4452.21
A4: Direct Transfer Costs | B4: =Nominal_cost_bsl_year!B4*(Nominal_cost_bsl_year!B$20/Nominal_cost_bsl_year!B$19)*B$19 -> 1227.866 | C4: =Nominal_cost_bsl_year!C4*(Nominal_cost_bsl_year!C$20/Nominal_cost_bsl_year!C$19)*C$19 -> 680.21343 | D4: =Nominal_cost_bsl_year!D4*(Nominal_cost_bsl_year!D$20/Nominal_cost_bsl_year!D$19)*D$19 -> 723.75477 | E4: =Nominal_cost_bsl_year!E4*(Nominal_cost_bsl_year!E$20/Nominal_cost_bsl_year!E$19)*E$19 -> 699.83225 | F4: =Nominal_cost_bsl_year!F4*(Nominal_cost_bsl_year!F$20/Nominal_cost_bsl_year!F$19)*F$19 -> 2048.1467 | G4: =Nominal_cost_bsl_year!G4*(Nominal_cost_bsl_year!G$20/Nominal_cost_bsl_year!G$19)*G$19 -> 1095.1214
A5: Asset Cost | B5: =Nominal_cost_bsl_year!B5*(Nominal_cost_bsl_year!B$20/Nominal_cost_bsl_year!B$19)*B$19 -> 1227.866 | C5: =Nominal_cost_bsl_year!C5*(Nominal_cost_bsl_year!C$20/Nominal_cost_bsl_year!C$19)*C$19 -> 451.38161 | D5: =Nominal_cost_bsl_year!D5*(Nominal_cost_bsl_year!D$20/Nominal_cost_bsl_year!D$19)*D$19 -> 536.88621 | E5: =Nominal_cost_bsl_year!E5*(Nominal_cost_bsl_year!E$20/Nominal_cost_bsl_year!E$19)*E$19 -> 437.3119 | F5: =Nominal_cost_bsl_year!F5*(Nominal_cost_bsl_year!F$20/Nominal_cost_bsl_year!F$19)*F$19 -> 1043.3262 | G5: =Nominal_cost_bsl_year!G5*(Nominal_cost_bsl_year!G$20/Nominal_cost_bsl_year!G$19)*G$19 -> 853.96521
A6: Food stipend | B6: =Nominal_cost_bsl_year!B6*(Nominal_cost_bsl_year!B$20/Nominal_cost_bsl_year!B$19)*B$19 -> 0 | C6: =Nominal_cost_bsl_year!C6*(Nominal_cost_bsl_year!C$20/Nominal_cost_bsl_year!C$19)*C$19 -> 228.83182 | D6: =Nominal_cost_bsl_year!D6*(Nominal_cost_bsl_year!D$20/Nominal_cost_bsl_year!D$19)*D$19 -> 186.86856 | E6: =Nominal_cost_bsl_year!E6*(Nominal_cost_bsl_year!E$20/Nominal_cost_bsl_year!E$19)*E$19 -> 262.52035 | F6: =Nominal_cost_bsl_year!F6*(Nominal_cost_bsl_year!F$20/Nominal_cost_bsl_year!F$19)*F$19 -> 910.94896 | G6: =Nominal_cost_bsl_year!G6*(Nominal_cost_bsl_year!G$20/Nominal_cost_bsl_year!G$19)*G$19 -> 241.15615
A7: Total Supervision Costs | B7: =Nominal_cost_bsl_year!B7*(Nominal_cost_bsl_year!B$20/Nominal_cost_bsl_year!B$19)*B$19 -> 1899.5424 | C7: =Nominal_cost_bsl_year!C7*(Nominal_cost_bsl_year!C$20/Nominal_cost_bsl_year!C$19)*C$19 -> 2832.41 | D7: =Nominal_cost_bsl_year!D7*(Nominal_cost_bsl_year!D$20/Nominal_cost_bsl_year!D$19)*D$19 -> 1632.5621 | E7: =Nominal_cost_bsl_year!E7*(Nominal_cost_bsl_year!E$20/Nominal_cost_bsl_year!E$19)*E$19 -> 406.82765 | F7: - | G7: =Nominal_cost_bsl_year!G7*(Nominal_cost_bsl_year!G$20/Nominal_cost_bsl_year!G$19)*G$19 -> 3357.0886
A8: Salaries of Implementing Organization Staff | B8: =Nominal_cost_bsl_year!B8*(Nominal_cost_bsl_year!B$20/Nominal_cost_bsl_year!B$19)*B$19 -> 346.8637 | C8: =Nominal_cost_bsl_year!C8*(Nominal_cost_bsl_year!C$20/Nominal_cost_bsl_year!C$19)*C$19 -> 1994.2149 | D8: =Nominal_cost_bsl_year!D8*(Nominal_cost_bsl_year!D$20/Nominal_cost_bsl_year!D$19)*D$19 -> 800.72945 | E8: =Nominal_cost_bsl_year!E8*(Nominal_cost_bsl_year!E$20/Nominal_cost_bsl_year!E$19)*E$19 -> 296.94858 | F8: - | G8: =Nominal_cost_bsl_year!G8*(Nominal_cost_bsl_year!G$20/Nominal_cost_bsl_year!G$19)*G$19 -> 2476.7609
A9: Materials | B9: =Nominal_cost_bsl_year!B9*(Nominal_cost_bsl_year!B$20/Nominal_cost_bsl_year!B$19)*B$19 -> 33.200338 | C9: =Nominal_cost_bsl_year!C9*(Nominal_cost_bsl_year!C$20/Nominal_cost_bsl_year!C$19)*C$19 -> 119.3945 | D9: =Nominal_cost_bsl_year!D9*(Nominal_cost_bsl_year!D$20/Nominal_cost_bsl_year!D$19)*D$19 -> 112.25028 | E9: =Nominal_cost_bsl_year!E9*(Nominal_cost_bsl_year!E$20/Nominal_cost_bsl_year!E$19)*E$19 -> 1.4968798 | F9: - | G9: =Nominal_cost_bsl_year!G9*(Nominal_cost_bsl_year!G$20/Nominal_cost_bsl_year!G$19)*G$19 -> 55.019271
A10: Training | B10: =Nominal_cost_bsl_year!B10*(Nominal_cost_bsl_year!B$20/Nominal_cost_bsl_year!B$19)*B$19 -> 849.90408 | C10: =Nominal_cost_bsl_year!C10*(Nominal_cost_bsl_year!C$20/Nominal_cost_bsl_year!C$19)*C$19 -> 43.799363 | D10: =Nominal_cost_bsl_year!D10*(Nominal_cost_bsl_year!D$20/Nominal_cost_bsl_year!D$19)*D$19 -> 121.18295 | E10: =Nominal_cost_bsl_year!E10*(Nominal_cost_bsl_year!E$20/Nominal_cost_bsl_year!E$19)*E$19 -> 18.5694 | F10: - | G10: =Nominal_cost_bsl_year!G10*(Nominal_cost_bsl_year!G$20/Nominal_cost_bsl_year!G$19)*G$19 -> 110.77679
A11: Travel Costs | B11: =Nominal_cost_bsl_year!B11*(Nominal_cost_bsl_year!B$20/Nominal_cost_bsl_year!B$19)*B$19 -> 173.65701 | C11: =Nominal_cost_bsl_year!C11*(Nominal_cost_bsl_year!C$20/Nominal_cost_bsl_year!C$19)*C$19 -> 293.09532 | D11: =Nominal_cost_bsl_year!D11*(Nominal_cost_bsl_year!D$20/Nominal_cost_bsl_year!D$19)*D$19 -> 210.38408 | E11: =Nominal_cost_bsl_year!E11*(Nominal_cost_bsl_year!E$20/Nominal_cost_bsl_year!E$19)*E$19 -> 16.708415 | F11: - | G11: =Nominal_cost_bsl_year!G11*(Nominal_cost_bsl_year!G$20/Nominal_cost_bsl_year!G$19)*G$19 -> 54.844421
A12: Other Expenses | B12: =Nominal_cost_bsl_year!B12*(Nominal_cost_bsl_year!B$20/Nominal_cost_bsl_year!B$19)*B$19 -> 495.91725 | C12: =Nominal_cost_bsl_year!C12*(Nominal_cost_bsl_year!C$20/Nominal_cost_bsl_year!C$19)*C$19 -> 381.90586 | D12: =Nominal_cost_bsl_year!D12*(Nominal_cost_bsl_year!D$20/Nominal_cost_bsl_year!D$19)*D$19 -> 388.01535 | E12: =Nominal_cost_bsl_year!E12*(Nominal_cost_bsl_year!E$20/Nominal_cost_bsl_year!E$19)*E$19 -> 73.104372 | F12: - | G12: =Nominal_cost_bsl_year!G12*(Nominal_cost_bsl_year!G$20/Nominal_cost_bsl_year!G$19)*G$19 -> 659.68727
A13: Start-up expenses | B13: =Nominal_cost_bsl_year!B13*(Nominal_cost_bsl_year!B$20/Nominal_cost_bsl_year!B$19)*B$19 -> 43.211838 | C13: =Nominal_cost_bsl_year!C13*(Nominal_cost_bsl_year!C$20/Nominal_cost_bsl_year!C$19)*C$19 -> 133.10853 | D13: =Nominal_cost_bsl_year!D13*(Nominal_cost_bsl_year!D$20/Nominal_cost_bsl_year!D$19)*D$19 -> 104.44449 | E13: =Nominal_cost_bsl_year!E13*(Nominal_cost_bsl_year!E$20/Nominal_cost_bsl_year!E$19)*E$19 -> 38.271575 | F13: - | G13: =Nominal_cost_bsl_year!G13*(Nominal_cost_bsl_year!G$20/Nominal_cost_bsl_year!G$19)*G$19 -> 45.460838
A14: Indirect Costs | B14: =Nominal_cost_bsl_year!B14*(Nominal_cost_bsl_year!B$20/Nominal_cost_bsl_year!B$19)*B$19 -> 420.62403 | C14: =Nominal_cost_bsl_year!C14*(Nominal_cost_bsl_year!C$20/Nominal_cost_bsl_year!C$19)*C$19 -> 1026.3223 | D14: =Nominal_cost_bsl_year!D14*(Nominal_cost_bsl_year!D$20/Nominal_cost_bsl_year!D$19)*D$19 -> 208.88897 | E14: =Nominal_cost_bsl_year!E14*(Nominal_cost_bsl_year!E$20/Nominal_cost_bsl_year!E$19)*E$19 -> 111.82096 | F14: =Nominal_cost_bsl_year!F14*(Nominal_cost_bsl_year!F$20/Nominal_cost_bsl_year!F$19)*F$19 -> 470.35927 | G14: =Nominal_cost_bsl_year!G14*(Nominal_cost_bsl_year!G$20/Nominal_cost_bsl_year!G$19)*G$19 -> 462.08805
A15: Total Costs, calculated as if all spent immediately at beginning of year 0 | B15: =Nominal_cost_bsl_year!B15*(Nominal_cost_bsl_year!B$20/Nominal_cost_bsl_year!B$19)*B$19 -> 3591.2442 | C15: =Nominal_cost_bsl_year!C15*(Nominal_cost_bsl_year!C$20/Nominal_cost_bsl_year!C$19)*C$19 -> 4672.0543 | D15: =Nominal_cost_bsl_year!D15*(Nominal_cost_bsl_year!D$20/Nominal_cost_bsl_year!D$19)*D$19 -> 2669.6503 | E15: =Nominal_cost_bsl_year!E15*(Nominal_cost_bsl_year!E$20/Nominal_cost_bsl_year!E$19)*E$19 -> 1256.7524 | F15: =Nominal_cost_bsl_year!F15*(Nominal_cost_bsl_year!F$20/Nominal_cost_bsl_year!F$19)*F$19 -> 5150.1363 | G15: =Nominal_cost_bsl_year!G15*(Nominal_cost_bsl_year!G$20/Nominal_cost_bsl_year!G$19)*G$19 -> 4959.7589
A16: Total Costs, Inflated to Year 3 at 5% annual discount rate | B16: =B15*(1+0.05)^3 -> 4157.3141 | C16: =C15*(1+0.05)^3 -> 5408.4868 | D16: =D15*(1+0.05)^3 -> 3090.454 | E16: =E15*(1+0.05)^3 -> 1454.848 | F16: =F15*(1+0.05)^3 -> 5961.9265 | G16: =G15*(1+0.05)^3 -> 5741.5409
A17: Total costs, inflated to year 3 at 7% annual discount rate | B17: =B15*(1+0.07)^3 -> 4399.4286 | C17: =C15*(1+0.07)^3 -> 5723.4674 | D17: =D15*(1+0.07)^3 -> 3270.4365 | E17: =E15*(1+0.07)^3 -> 1539.5758 | F17: =F15*(1+0.07)^3 -> 6309.1384 | G17: =G15*(1+0.07)^3 -> 6075.9179
A18: Total costs, inflated to year 3 at 10% annual discount rate | B18: =B15*(1+0.1)^3 -> 4779.9461 | C18: =C15*(1+0.1)^3 -> 6218.5042 | D18: =D15*(1+0.1)^3 -> 3553.3046 | E18: =E15*(1+0.1)^3 -> 1672.7375 | F18: =F15*(1+0.1)^3 -> 6854.8314 | G18: =G15*(1+0.1)^3 -> 6601.439
A19: Scalar from nominal to PPP terms | B19: 3.4084689 | C19: 2.1882857 | D19: 1.8991812 | E19: 3.5153061 | F19: 4.439842 | G19: 1.8388514
A21: Panel B: Benefits per Household, USD PPP, All Values Inflated or Deflated to Year 3 at 5% annual social discount rate
A22: Monthly Non-durable Consumption ITT per capita, Year 2 (from tables) | B22: 6.4 | C22: 2.79 | D22: 0.89 | E22: 6.89 | F22: 7.74 | G22: 5.18
A23: Household Size, Year 2 | B23: 5.59 | C23: 8.34 | D23: 5.88 | E23: 3.96 | F23: 6.29 | G23: 5.195
A24: Year 2 Annual Consumption ITT Treatment Effect, pre-NPV conversion | B24: =B22*B23*12 -> 429.312 | C24: =C22*C23*12 -> 279.2232 | D24: =D22*D23*12 -> 62.7984 | E24: =E22*E23*12 -> 327.4128 | F24: =F22*F23*12 -> 584.2152 | G24: =G22*G23*12 -> 322.9212
A25: Year 1 Annual Non-durable Consumption ITT, assuming treatment effect equal to Year 2 | B25: =B$24*(1+0.05) -> 450.7776 | C25: =C$24*(1+0.05) -> 293.18436 | D25: =D$24*(1+0.05) -> 65.93832 | E25: =E$24*(1+0.05) -> 343.78344 | F25: =F$24*(1+0.05) -> 613.42596 | G25: =G$24*(1+0.05) -> 339.06726
A26: Year 1 Annual Non-durable Consumption ITT Treatment Effect, using 7% discount rate | B26: =B$24*(1+0.07) -> 459.36384 | C26: =C$24*(1+0.07) -> 298.76882 | D26: =D$24*(1+0.07) -> 67.194288 | E26: =E$24*(1+0.07) -> 350.3317 | F26: =F$24*(1+0.07) -> 625.11026 | G26: =G$24*(1+0.07) -> 345.52568
A27: Year 1 Annual Non-durable consumption ITT, Treatment Effect, using 10% discount rate | B27: =B$24*(1+0.1) -> 472.2432 | C27: =C$24*(1+0.1) -> 307.14552 | D27: =D$24*(1+0.1) -> 69.07824 | E27: =E$24*(1+0.1) -> 360.15408 | F27: =F$24*(1+0.1) -> 642.63672 | G27: =G$24*(1+0.1) -> 355.21332
A28: Year 2 Annual Non-durable Consumption ITT Treatment Effect | B28: =B$24*(1+0.05) -> 450.7776 | C28: =C$24*(1+0.05) -> 293.18436 | D28: =D$24*(1+0.05) -> 65.93832 | E28: =E$24*(1+0.05) -> 343.78344 | F28: =F$24*(1+0.05) -> 613.42596 | G28: =G$24*(1+0.05) -> 339.06726
A29: Year 2 Annual consumption ITT, using 7% discount rate | B29: =B$24*(1+0.07) -> 459.36384 | C29: =C$24*(1+0.07) -> 298.76882 | D29: =D$24*(1+0.07) -> 67.194288 | E29: =E$24*(1+0.07) -> 350.3317 | F29: =F$24*(1+0.07) -> 625.11026 | G29: =G$24*(1+0.07) -> 345.52568
A30: Year 2 annual Consumption ITT, using 10% discount rate | B30: =B$24*(1+0.1) -> 472.2432 | C30: =C$24*(1+0.1) -> 307.14552 | D30: =D$24*(1+0.1) -> 69.07824 | E30: =E$24*(1+0.1) -> 360.15408 | F30: =F$24*(1+0.1) -> 642.63672 | G30: =G$24*(1+0.1) -> 355.21332
A31: Year 3 Household Asset ITT Treatment Effect | B31: 62.9 | C31: 15.186207 | D31: -19.9 | E31: 6.1551931 | F31: 6.55 | G31: 37.1
A32: Monthly Non-Durable Consumption ITT per capita, Year 3 (from tables) | B32: 6.32 | C32: 3.26 | D32: -3.08 | E32: 5.51 | F32: 5.71 | G32: 4.18
A33: Monthly Total Consumption ITT per capita, Year 3 (from tables) | B33: 7.37 | C33: 3.22 | D33: -4.45 | E33: 6.18 | F33: 5.98 | G33: 6.18
A34: Household Size, Year 3 | B34: 5.59 | C34: 8.48 | D34: 5.91 | E34: 3.79 | F34: 6.58 | G34: 5.24
A35: Year 3 Non-durable Annual Consumption ITT Treatment Effect | B35: =B32*B34*12 -> 423.9456 | C35: =C32*C34*12 -> 331.7376 | D35: =D32*D34*12 -> -218.4336 | E35: =E32*E34*12 -> 250.5948 | F35: =F32*F34*12 -> 450.8616 | G35: =G32*G34*12 -> 262.8384
A36: Year 3 Total Consumption ITT Treatment Effect | B36: =B33*B34*12 -> 494.3796 | C36: =C33*C34*12 -> 327.6672 | D36: =D33*D34*12 -> -315.594 | E36: =E33*E34*12 -> 281.0664 | F36: =F33*F34*12 -> 472.1808 | G36: =G33*G34*12 -> 388.5984
A37: Year 4 Onward Total Consumption ITT Treatment Effect, assuming Year 3 gains persist in perpetuity | B37: =(B$36/(1+0.05))/0.05 -> 9416.7543 | C37: =(C$36/(1+0.05))/0.05 -> 6241.28 | D37: =(D$36/(1+0.05))/0.05 -> -6011.3143 | E37: =(E$36/(1+0.05))/0.05 -> 5353.6457 | F37: =(F$36/(1+0.05))/0.05 -> 8993.92 | G37: =(G$36/(1+0.05))/0.05 -> 7401.8743
A38: Future Non-durable Consumption ITT Treatment Effect in perpetuity, assuming 7% discount | B38: =(B$36/(1+0.07))/0.07 -> 6600.5287 | C38: =(C$36/(1+0.07))/0.07 -> 4374.729 | D38: =(D$36/(1+0.07))/0.07 -> -4213.5381 | E38: =(E$36/(1+0.07))/0.07 -> 3752.5554 | F38: =(F$36/(1+0.07))/0.07 -> 6304.1495 | G38: =(G$36/(1+0.07))/0.07 -> 5188.2296
A39: Future Non-durable Consumption ITT Treatment Effect in perpetuity, assuming 10% discount | B39: =(B$36/(1+0.1))/0.1 -> 4494.36 | C39: =(C$36/(1+0.1))/0.1 -> 2978.7927 | D39: =(D$36/(1+0.1))/0.1 -> -2869.0364 | E39: =(E$36/(1+0.1))/0.1 -> 2555.1491 | F39: =(F$36/(1+0.1))/0.1 -> 4292.5527 | G39: =(G$36/(1+0.1))/0.1 -> 3532.7127
A40: Total Benefits | B40: =B25+B28+B31+B35+B37 -> 10805.155 | C40: =C25+C28+C31+C35+C37 -> 7174.5725 | D40: =D25+D28+D31+D35+D37 -> -6117.7712 | E40: =E25+E28+E31+E35+E37 -> 6297.9626 | F40: =F25+F28+F31+F35+F37 -> 10678.184 | G40: =G25+G28+G31+G35+G37 -> 8379.9472
A41: Total benefits, assuming 7% discount rate: (3-7) + (4-7) + (5) + (6) + (7-7) | B41: =B26+B29+B31+B35+B38 -> 8006.102 | C41: =C26+C29+C31+C35+C38 -> 5319.1904 | D41: =D26+D29+D31+D35+D38 -> -4317.4831 | E41: =E26+E29+E31+E35+E38 -> 4709.9688 | F41: =F26+F29+F31+F35+F38 -> 8011.7817 | G41: =G26+G29+G31+G35+G38 -> 6179.2194
...

Sheet Nominal_cost_bsl_year
A1: Program Costs per Participant, USD at baseline year (nominal) | B1: Ethiopia | C1: Ghana | D1: Honduras | E1: India | F1: Pakistan | G1: Peru
A3: Total Direct Costs | B3: 844.51602 | C3: 1524.077 | D3: 1123.5285 | E3: 275.46404 | F3: 957.90473 | G3: 2298.838
A4: Direct Transfer Costs | B4: 331.56927 | C4: 295.13487 | D4: 345.09752 | E4: 174.19861 | F4: 419.23566 | G4: 565.451
A5: Asset Cost | B5: 331.56927 | C5: 195.84802 | D5: 255.99569 | E5: 108.85341 | F5: 213.5587 | G5: 440.93331
A6: Food stipend | B6: 0 | C6: 99.286852 | D6: 89.101833 | E6: 65.345203 | F6: 186.46237 | G6: 124.51769
A7: Total Supervision Costs | B7: 512.94675 | C7: 1228.9422 | D7: 778.43098 | E7: 101.26543 | F7: - | G7: 1733.387
A8: Salaries of Implementing Organization Staff | B8: 93.666037 | C8: 865.26133 | D8: 381.80024 | E8: 73.914901 | F8: - | G8: 1278.8417
A9: Materials | B9: 8.96532 | C9: 51.803564 | D9: 53.522679 | E9: 0.37259555 | F9: - | G9: 28.408451
A10: Training | B10: 229.50556 | C10: 19.003917 | D10: 57.781914 | E10: 4.6221988 | F10: - | G10: 57.198089
A11: Travel Costs | B11: 46.893819 | C11: 127.16987 | D11: 100.3144 | E11: 4.1589719 | F11: - | G11: 28.31817
A12: Other Expenses | B12: 133.91601 | C12: 165.70349 | D12: 185.01175 | E12: 18.196761 | F12: - | G12: 340.62054
A13: Start-up expenses | B13: 11.668796 | C13: 57.753884 | D13: 49.800753 | E13: 9.5263619 | F13: - | G13: 23.473085
A14: Indirect Costs | B14: 113.58406 | C14: 445.30657 | D14: 99.601507 | E14: 27.833895 | F14: 96.277957 | G14: 238.59287
A15: Total Program Costs | B15: 969.76887 | C15: 2027.1375 | D15: 1272.9308 | E15: 312.8243 | F15: 1054.1827 | G15: 2560.904
A16: Year of Baseline Survey | B16: 2010 | C16: 2011 | D16: 2009 | E16: 2007 | F16: 2008 | G16: 2011
A17: Exchange rate, year of baseline survey | B17: 14.2474 | C17: 1.5318 | D17: 18.555 | E17: 41.34 | F17: 70.2383 | G17: 2.7215
A18: PPP Exchange rate, year of baseline survey | B18: 4.18 | C18: 0.7 | D18: 9.77 | E18: 11.76 | F18: 15.82 | G18: 1.48
A19: US CPI of Baseline Year | B19: 218.056 | C19: 224.939 | D19: 214.537 | E19: 207.3 | F19: 215.303 | G19: 224.939
A20: US CPI of 2014 (as of January 15) | B20: 236.9111 | C20: 236.9111 | D20: 236.9111 | E20: 236.9111 | F20: 236.9111 | G20: 236.9111
A21: Scalar from nominal to PPP terms | B21: =B17/B18 -> 3.4084689 | C21: =C17/C18 -> 2.1882857 | D21: =D17/D18 -> 1.8991812 | E21: =E17/E18 -> 3.5153061 | F21: =F17/F18 -> 4.439842 | G21: =G17/G18 -> 1.8388514

Sheet IRR_Inputs
B1: Ethiopia | C1: Ghana | D1: Honduras | E1: India | F1: Pakistan | G1: Peru
A2: ITT Year 2: Nondurable consumption | B2: =Table4_Cost_Benefit_Analysis!B24 -> 429.312 | C2: =Table4_Cost_Benefit_Analysis!C24 -> 279.2232 | D2: =Table4_Cost_Benefit_Analysis!D24 -> 62.7984 | E2: =Table4_Cost_Benefit_Analysis!E24 -> 327.4128 | F2: =Table4_Cost_Benefit_Analysis!F24 -> 584.2152 | G2: =Table4_Cost_Benefit_Analysis!G24 -> 322.9212
A3: ITT Year 3: Nondurable consumption | B3: =Table4_Cost_Benefit_Analysis!B35 -> 423.9456 | C3: =Table4_Cost_Benefit_Analysis!C35 -> 331.7376 | D3: =Table4_Cost_Benefit_Analysis!D35 -> -218.4336 | E3: =Table4_Cost_Benefit_Analysis!E35 -> 250.5948 | F3: =Table4_Cost_Benefit_Analysis!F35 -> 450.8616 | G3: =Table4_Cost_Benefit_Analysis!G35 -> 262.8384
A4: ITT Year 3: Household assets | B4: =Table4_Cost_Benefit_Analysis!B31 -> 62.9 | C4: =Table4_Cost_Benefit_Analysis!C31 -> 15.186207 | D4: =Table4_Cost_Benefit_Analysis!D31 -> -19.9 | E4: =Table4_Cost_Benefit_Analysis!E31 -> 6.1551931 | F4: =Table4_Cost_Benefit_Analysis!F31 -> 6.55 | G4: =Table4_Cost_Benefit_Analysis!G31 -> 37.1
A5: ITT Year 3+: Total consumption | B5: =Table4_Cost_Benefit_Analysis!B36 -> 494.3796 | C5: =Table4_Cost_Benefit_Analysis!C36 -> 327.6672 | D5: =Table4_Cost_Benefit_Analysis!D36 -> -315.594 | E5: =Table4_Cost_Benefit_Analysis!E36 -> 281.0664 | F5: =Table4_Cost_Benefit_Analysis!F36 -> 472.1808 | G5: =Table4_Cost_Benefit_Analysis!G36 -> 388.5984
A6: Cost | B6: =Table4_Cost_Benefit_Analysis!B15 -> 3591.2442 | C6: =Table4_Cost_Benefit_Analysis!C15 -> 4672.0543 | D6: =Table4_Cost_Benefit_Analysis!D15 -> 2669.6503 | E6: =Table4_Cost_Benefit_Analysis!E15 -> 1256.7524 | F6: =Table4_Cost_Benefit_Analysis!F15 -> 5150.1363 | G6: =Table4_Cost_Benefit_Analysis!G15 -> 4959.7589

Sheet IRR_Calculations
B1: Ethiopia | C1: Ghana | D1: Honduras | E1: India | F1: Pakistan | G1: Peru
A2: 0 | B2: =-IRR_Inputs!B6 -> -3591.2442 | C2: =-IRR_Inputs!C6 -> -4672.0543 | D2: =-IRR_Inputs!D6 -> -2669.6503 | E2: =-IRR_Inputs!E6 -> -1256.7524 | F2: =-IRR_Inputs!F6 -> -5150.1363 | G2: =-IRR_Inputs!G6 -> -4959.7589
A3: 1 | B3: =IRR_Inputs!B2 -> 429.312 | C3: =IRR_Inputs!C2 -> 279.2232 | D3: =IRR_Inputs!D2 -> 62.7984 | E3: =IRR_Inputs!E2 -> 327.4128 | F3: =IRR_Inputs!F2 -> 584.2152 | G3: =IRR_Inputs!G2 -> 322.9212
A4: 2 | B4: =IRR_Inputs!B2 -> 429.312 | C4: =IRR_Inputs!C2 -> 279.2232 | D4: =IRR_Inputs!D2 -> 62.7984 | E4: =IRR_Inputs!E2 -> 327.4128 | F4: =IRR_Inputs!F2 -> 584.2152 | G4: =IRR_Inputs!G2 -> 322.9212
A5: 3 | B5: =IRR_Inputs!B3+IRR_Inputs!B4 -> 486.8456 | C5: =IRR_Inputs!C3+IRR_Inputs!C4 -> 346.92381 | D5: =IRR_Inputs!D3+IRR_Inputs!D4 -> -238.3336 | E5: =IRR_Inputs!E3+IRR_Inputs!E4 -> 256.74999 | F5: =IRR_Inputs!F3+IRR_Inputs!F4 -> 457.4116 | G5: =IRR_Inputs!G3+IRR_Inputs!G4 -> 299.9384
A6: 4 | B6: =IRR_Inputs!B$5 -> 494.3796 | C6: =IRR_Inputs!C$5 -> 327.6672 | D6: =IRR_Inputs!D$5 -> -315.594 | E6: =IRR_Inputs!E$5 -> 281.0664 | F6: =IRR_Inputs!F$5 -> 472.1808 | G6: =IRR_Inputs!G$5 -> 388.5984
A7: 5 | B7: =IRR_Inputs!B$5 -> 494.3796 | C7: =IRR_Inputs!C$5 -> 327.6672 | D7: =IRR_Inputs!D$5 -> -315.594 | E7: =IRR_Inputs!E$5 -> 281.0664 | F7: =IRR_Inputs!F$5 -> 472.1808 | G7: =IRR_Inputs!G$5 -> 388.5984
A8: 6 | B8: =IRR_Inputs!B$5 -> 494.3796 | C8: =IRR_Inputs!C$5 -> 327.6672 | D8: =IRR_Inputs!D$5 -> -315.594 | E8: =IRR_Inputs!E$5 -> 281.0664 | F8: =IRR_Inputs!F$5 -> 472.1808 | G8: =IRR_Inputs!G$5 -> 388.5984
A9: 7 | B9: =IRR_Inputs!B$5 -> 494.3796 | C9: =IRR_Inputs!C$5 -> 327.6672 | D9: =IRR_Inputs!D$5 -> -315.594 | E9: =IRR_Inputs!E$5 -> 281.0664 | F9: =IRR_Inputs!F$5 -> 472.1808 | G9: =IRR_Inputs!G$5 -> 388.5984
A10: 8 | B10: =IRR_Inputs!B$5 -> 494.3796 | C10: =IRR_Inputs!C$5 -> 327.6672 | D10: =IRR_Inputs!D$5 -> -315.594 | E10: =IRR_Inputs!E$5 -> 281.0664 | F10: =IRR_Inputs!F$5 -> 472.1808 | G10: =IRR_Inputs!G$5 -> 388.5984
A11: 9 | B11: =IRR_Inputs!B$5 -> 494.3796 | C11: =IRR_Inputs!C$5 -> 327.6672 | D11: =IRR_Inputs!D$5 -> -315.594 | E11: =IRR_Inputs!E$5 -> 281.0664 | F11: =IRR_Inputs!F$5 -> 472.1808 | G11: =IRR_Inputs!G$5 -> 388.5984
A12: 10 | B12: =IRR_Inputs!B$5 -> 494.3796 | C12: =IRR_Inputs!C$5 -> 327.6672 | D12: =IRR_Inputs!D$5 -> -315.594 | E12: =IRR_Inputs!E$5 -> 281.0664 | F12: =IRR_Inputs!F$5 -> 472.1808 | G12: =IRR_Inputs!G$5 -> 388.5984
A13: 11 | B13: =IRR_Inputs!B$5 -> 494.3796 | C13: =IRR_Inputs!C$5 -> 327.6672 | D13: =IRR_Inputs!D$5 -> -315.594 | E13: =IRR_Inputs!E$5 -> 281.0664 | F13: =IRR_Inputs!F$5 -> 472.1808 | G13: =IRR_Inputs!G$5 -> 388.5984
A14: 12 | B14: =IRR_Inputs!B$5 -> 494.3796 | C14: =IRR_Inputs!C$5 -> 327.6672 | D14: =IRR_Inputs!D$5 -> -315.594 | E14: =IRR_Inputs!E$5 -> 281.0664 | F14: =IRR_Inputs!F$5 -> 472.1808 | G14: =IRR_Inputs!G$5 -> 388.5984
A15: 13 | B15: =IRR_Inputs!B$5 -> 494.3796 | C15: =IRR_Inputs!C$5 -> 327.6672 | D15: =IRR_Inputs!D$5 -> -315.594 | E15: =IRR_Inputs!E$5 -> 281.0664 | F15: =IRR_Inputs!F$5 -> 472.1808 | G15: =IRR_Inputs!G$5 -> 388.5984
A16: 14 | B16: =IRR_Inputs!B$5 -> 494.3796 | C16: =IRR_Inputs!C$5 -> 327.6672 | D16: =IRR_Inputs!D$5 -> -315.594 | E16: =IRR_Inputs!E$5 -> 281.0664 | F16: =IRR_Inputs!F$5 -> 472.1808 | G16: =IRR_Inputs!G$5 -> 388.5984
A17: 15 | B17: =IRR_Inputs!B$5 -> 494.3796 | C17: =IRR_Inputs!C$5 -> 327.6672 | D17: =IRR_Inputs!D$5 -> -315.594 | E17: =IRR_Inputs!E$5 -> 281.0664 | F17: =IRR_Inputs!F$5 -> 472.1808 | G17: =IRR_Inputs!G$5 -> 388.5984
... A162: 160 | B162: =IRR_Inputs!B$5 -> 494.3796 | C162: =IRR_Inputs!C$5 -> 327.6672 | D162: =IRR_Inputs!D$5 -> -315.594 | E162: =IRR_Inputs!E$5 -> 281.0664 | F162: =IRR_Inputs!F$5 -> 472.1808 | G162: =IRR_Inputs!G$5 -> 388.5984
